<mujoco model="g1_29dof_rev_1_0_with_inspire_hand_DFQ">
  <compiler angle="radian" meshdir="meshes/"/>

    <default>
        <default class="g1">
            <default class="visual">
                <geom group="2" type="mesh" density="0" material="silver"/>
            </default>
            <default class="collision">
                <geom group="3" rgba=".2 .6 .2 .3" type="capsule"/>
                <default class="foot_box">
                    <geom pos="0.04 0 -0.02" size="0.12 0.04 0.02" type="box" group="4"/>
                </default>
                <default class="foot_capsule">
                    <geom group="3" type="capsule" size="0.01"/>
                </default>
            </default>
            <site group="5" rgba="1 0 0 1"/>
            <!-- Disable all contacts and use explicit contact pairs. -->
            <geom condim="1" contype="0" conaffinity="0"/>
            <joint frictionloss="0.1" solimplimit="0 0.99 0.01" solreflimit=".008 1"/>
            <!--      <motor inheritrange="1" kp="75" kv="2"/>-->

            <default class="hip">
                <default class="hip_pitch">
                    <joint axis="0 1 0" range="-2.5307 2.8798" actuatorfrcrange="-88 88" armature="0.01017752004"/>
                </default>
                <default class="hip_roll">
                    <joint axis="1 0 0" range="-0.5236 2.9671" actuatorfrcrange="-139 139" armature="0.025101925"/>
                </default>
                <default class="hip_yaw">
                    <joint axis="0 0 1" range="-2.7576 2.7576" actuatorfrcrange="-88 88" armature="0.01017752004"/>
                </default>
            </default>
            <default class="knee">
                <joint axis="0 1 0" range="-0.087267 2.8798" actuatorfrcrange="-139 139" armature="0.025101925"/>
            </default>
            <default class="ankle">
                <!--        <motor kp="20" kv="2"/>-->
                <default class="ankle_pitch">
                    <joint axis="0 1 0" range="-0.87267 0.5236" actuatorfrcrange="-50 50" armature="0.00721945"/>
                </default>
                <default class="ankle_roll">
                    <joint axis="1 0 0" range="-0.2618 0.2618" actuatorfrcrange="-50 50" armature="0.00721945"/>
                </default>
            </default>

            <default class="waist_yaw">
                <joint axis="0 0 1" range="-2.618 2.618" actuatorfrcrange="-88 88" armature="0.01017752004"/>
            </default>
            <default class="waist_pitch">
                <joint axis="0 1 0" range="-0.52 0.52" actuatorfrcrange="-50 50" armature="0.00721945"/>
            </default>
            <default class="waist_roll">
                <joint axis="1 0 0" range="-0.52 0.52" actuatorfrcrange="-50 50" armature="0.00721945"/>
            </default>

            <default class="shoulder">
                <default class="shoulder_pitch">
                    <joint axis="0 1 0" range="-3.0892 2.6704" actuatorfrcrange="-25 25" armature="0.003609725"/>
                </default>
                <default class="shoulder_roll">
                    <joint axis="1 0 0" actuatorfrcrange="-25 25" armature="0.003609725"/>
                </default>
                <default class="shoulder_yaw">
                    <joint axis="0 0 1" range="-2.618 2.618" actuatorfrcrange="-25 25" armature="0.003609725"/>
                </default>
            </default>

            <default class="elbow">
                <joint axis="0 1 0" range="-1.0472 2.0944" actuatorfrcrange="-25 25" armature="0.003609725"/>
            </default>

            <default class="wrist">
                <!--        <motor kp="20" kv="2"/>-->
                <default class="wrist_roll">
                    <joint axis="1 0 0" range="-1.97222 1.97222" actuatorfrcrange="-25 25" armature="0.003609725"/>
                </default>
                <default class="wrist_pitch">
                    <joint axis="0 1 0" range="-1.61443 1.61443" actuatorfrcrange="-5 5" armature="0.00425"/>
                </default>
                <default class="wrist_yaw">
                    <joint axis="0 0 1" range="-1.61443 1.61443" actuatorfrcrange="-5 5" armature="0.00425"/>
                </default>
            </default>
        </default>
    </default>

  <asset>
    <mesh name="pelvis" file="pelvis.STL"/>
    <mesh name="pelvis_contour_link" file="pelvis_contour_link.STL"/>
    <mesh name="left_hip_pitch_link" file="left_hip_pitch_link.STL"/>
    <mesh name="left_hip_roll_link" file="left_hip_roll_link.STL"/>
    <mesh name="left_hip_yaw_link" file="left_hip_yaw_link.STL"/>
    <mesh name="left_knee_link" file="left_knee_link.STL"/>
    <mesh name="left_ankle_pitch_link" file="left_ankle_pitch_link.STL"/>
    <mesh name="left_ankle_roll_link" file="left_ankle_roll_link.STL"/>
    <mesh name="right_hip_pitch_link" file="right_hip_pitch_link.STL"/>
    <mesh name="right_hip_roll_link" file="right_hip_roll_link.STL"/>
    <mesh name="right_hip_yaw_link" file="right_hip_yaw_link.STL"/>
    <mesh name="right_knee_link" file="right_knee_link.STL"/>
    <mesh name="right_ankle_pitch_link" file="right_ankle_pitch_link.STL"/>
    <mesh name="right_ankle_roll_link" file="right_ankle_roll_link.STL"/>
    <mesh name="waist_yaw_link_rev_1_0" file="waist_yaw_link_rev_1_0.STL"/>
    <mesh name="waist_roll_link_rev_1_0" file="waist_roll_link_rev_1_0.STL"/>
    <mesh name="torso_link_rev_1_0" file="torso_link_rev_1_0.STL"/>
    <mesh name="logo_link" file="logo_link.STL"/>
    <mesh name="head_link" file="head_link.STL"/>
    <mesh name="waist_support_link" file="waist_support_link.STL"/>
    <mesh name="left_shoulder_pitch_link" file="left_shoulder_pitch_link.STL"/>
    <mesh name="left_shoulder_roll_link" file="left_shoulder_roll_link.STL"/>
    <mesh name="left_shoulder_yaw_link" file="left_shoulder_yaw_link.STL"/>
    <mesh name="left_elbow_link" file="left_elbow_link.STL"/>
    <mesh name="left_wrist_roll_link" file="left_wrist_roll_link.STL"/>
    <mesh name="left_wrist_pitch_link" file="left_wrist_pitch_link.STL"/>
    <mesh name="left_wrist_yaw_link" file="left_wrist_yaw_link.STL"/>
    <mesh name="right_shoulder_pitch_link" file="right_shoulder_pitch_link.STL"/>
    <mesh name="right_shoulder_roll_link" file="right_shoulder_roll_link.STL"/>
    <mesh name="right_shoulder_yaw_link" file="right_shoulder_yaw_link.STL"/>
    <mesh name="right_elbow_link" file="right_elbow_link.STL"/>
    <mesh name="right_wrist_roll_link" file="right_wrist_roll_link.STL"/>
    <mesh name="right_wrist_pitch_link" file="right_wrist_pitch_link.STL"/>
    <mesh name="right_wrist_yaw_link" file="right_wrist_yaw_link.STL"/>
    <mesh name="left_base_link" file="left_base_link.STL"/>
    <mesh name="left_thumb_metacarpal_Link" file="left_thumb_metacarpal_Link.STL"/>
    <mesh name="left_thumb_proximal_Link" file="left_thumb_proximal_Link.STL"/>
    <mesh name="left_thumb_distal_Link" file="left_thumb_distal_Link.STL"/>
    <mesh name="left_thumb_tip_Link" file="left_thumb_tip_Link.STL"/>
    <mesh name="left_index_proximal_Link" file="left_index_proximal_Link.STL"/>
    <mesh name="left_index_distal_Link" file="left_index_distal_Link.STL"/>
    <mesh name="left_index_tip_Link" file="left_index_tip_Link.STL"/>
    <mesh name="left_middle_proximal_Link" file="left_middle_proximal_Link.STL"/>
    <mesh name="left_middle_distal_Link" file="left_middle_distal_Link.STL"/>
    <mesh name="left_middle_tip_Link" file="left_middle_tip_Link.STL"/>
    <mesh name="left_ring_proximal_Link" file="left_ring_proximal_Link.STL"/>
    <mesh name="left_ring_distal_Link" file="left_ring_distal_Link.STL"/>
    <mesh name="left_ring_tip_Link" file="left_ring_tip_Link.STL"/>
    <mesh name="left_pinky_proximal_Link" file="left_pinky_proximal_Link.STL"/>
    <mesh name="left_pinky_distal_Link" file="left_pinky_distal_Link.STL"/>
    <mesh name="left_pinky_tip_Link" file="left_pinky_tip_Link.STL"/>
    <mesh name="right_base_link" file="right_base_link.STL"/>
    <mesh name="right_thumb_metacarpal_link" file="right_thumb_metacarpal_link.STL"/>
    <mesh name="right_thumb_proximal_link" file="right_thumb_proximal_link.STL"/>
    <mesh name="right_thumb_distal_link" file="right_thumb_distal_link.STL"/>
    <mesh name="right_thumb_tip" file="right_thumb_tip.STL"/>
    <mesh name="right_index_proximal_link" file="right_index_proximal_link.STL"/>
    <mesh name="right_index_distal_link" file="right_index_distal_link.STL"/>
    <mesh name="right_index_tip" file="right_index_tip.STL"/>
    <mesh name="right_middle_proximal_link" file="right_middle_proximal_link.STL"/>
    <mesh name="right_middle_distal_link" file="right_middle_distal_link.STL"/>
    <mesh name="right_middle_tip" file="right_middle_tip.STL"/>
    <mesh name="right_ring_proximal_link" file="right_ring_proximal_link.STL"/>
    <mesh name="right_ring_distal_link" file="right_ring_distal_link.STL"/>
    <mesh name="right_ring_tip" file="right_ring_tip.STL"/>
    <mesh name="right_pinky_proximal_link" file="right_pinky_proximal_link.STL"/>
    <mesh name="right_pinky_distal_link" file="right_pinky_distal_link.STL"/>
    <mesh name="right_pinky_tip" file="right_pinky_tip.STL"/>
  </asset>

  <worldbody>
  <light name="spotlight" mode="targetbodycom" target="pelvis" pos="0 -2 4" exponent="20"/>
  <body name="pelvis" pos="0 0 0.793" childclass="g1">
    <camera name="track" pos="1.734 -1.135 .35" xyaxes="0.552 0.834 -0.000 -0.170 0.112 0.979" mode="trackcom"/>
    <inertial pos="0 0 -0.07605" quat="1 0 -0.000399148 0" mass="3.813"
              diaginertia="0.010549 0.0093089 0.0079184"/>
    <freejoint name="floating_base_joint"/>
    <site name="imu_in_pelvis" size="0.01" pos="0.04525 0 -0.08339"/>
    <geom type="mesh" contype="0" conaffinity="0" group="1" density="0" rgba="0.2 0.2 0.2 1" mesh="pelvis"/>
    <geom type="mesh" contype="0" conaffinity="0" group="1" density="0" rgba="0.7 0.7 0.7 1" mesh="pelvis_contour_link"/>
    <geom type="mesh" rgba="0.7 0.7 0.7 1" mesh="pelvis_contour_link"/>
    <body name="left_hip_pitch_link" pos="0 0.064452 -0.1027">
      <inertial pos="0.002741 0.047791 -0.02606" quat="0.954862 0.293964 0.0302556 0.030122" mass="1.35" diaginertia="0.00181517 0.00153422 0.00116212"/>
      <joint name="left_hip_pitch_joint" pos="0 0 0" axis="0 1 0" range="-2.5307 2.8798" actuatorfrcrange="-88 88"/>
      <geom type="mesh" contype="0" conaffinity="0" group="1" density="0" rgba="0.2 0.2 0.2 1" mesh="left_hip_pitch_link"/>
      <geom type="mesh" rgba="0.2 0.2 0.2 1" mesh="left_hip_pitch_link"/>
      <body name="left_hip_roll_link" pos="0 0.052 -0.030465" quat="0.996179 0 -0.0873386 0">
        <inertial pos="0.029812 -0.001045 -0.087934" quat="0.977808 -1.97119e-05 0.205576 -0.0403793" mass="1.52" diaginertia="0.00254986 0.00241169 0.00148755"/>
        <joint name="left_hip_roll_joint" pos="0 0 0" axis="1 0 0" range="-0.5236 2.9671" actuatorfrcrange="-139 139"/>
        <geom type="mesh" contype="0" conaffinity="0" group="1" density="0" rgba="0.7 0.7 0.7 1" mesh="left_hip_roll_link"/>
        <geom type="mesh" rgba="0.7 0.7 0.7 1" mesh="left_hip_roll_link"/>
        <body name="left_hip_yaw_link" pos="0.025001 0 -0.12412">
          <inertial pos="-0.057709 -0.010981 -0.15078" quat="0.600598 0.15832 0.223482 0.751181" mass="1.702" diaginertia="0.00776166 0.00717575 0.00160139"/>
          <joint name="left_hip_yaw_joint" pos="0 0 0" axis="0 0 1" range="-2.7576 2.7576" actuatorfrcrange="-88 88"/>
          <geom type="mesh" contype="0" conaffinity="0" group="1" density="0" rgba="0.7 0.7 0.7 1" mesh="left_hip_yaw_link"/>
          <geom type="mesh" rgba="0.7 0.7 0.7 1" mesh="left_hip_yaw_link"/>
          <body name="left_knee_link" pos="-0.078273 0.0021489 -0.17734" quat="0.996179 0 0.0873386 0">
            <inertial pos="0.005457 0.003964 -0.12074" quat="0.923418 -0.0327699 0.0158246 0.382067" mass="1.932" diaginertia="0.0113804 0.0112778 0.00146458"/>
            <joint name="left_knee_joint" pos="0 0 0" axis="0 1 0" range="-0.087267 2.8798" actuatorfrcrange="-139 139"/>
            <geom type="mesh" contype="0" conaffinity="0" group="1" density="0" rgba="0.7 0.7 0.7 1" mesh="left_knee_link"/>
            <geom type="mesh" rgba="0.7 0.7 0.7 1" mesh="left_knee_link"/>
            <body name="left_ankle_pitch_link" pos="0 -9.4445e-05 -0.30001">
              <inertial pos="-0.007269 0 0.011137" quat="0.603053 0.369225 0.369225 0.603053" mass="0.074" diaginertia="1.89e-05 1.40805e-05 6.9195e-06"/>
              <joint name="left_ankle_pitch_joint" pos="0 0 0" axis="0 1 0" range="-0.87267 0.5236" actuatorfrcrange="-35 35"/>
              <geom type="mesh" contype="0" conaffinity="0" group="1" density="0" rgba="0.7 0.7 0.7 1" mesh="left_ankle_pitch_link"/>
              <geom type="mesh" rgba="0.7 0.7 0.7 1" mesh="left_ankle_pitch_link"/>
              <body name="left_ankle_roll_link" pos="0 0 -0.017558">
                <inertial pos="0.026505 0 -0.016425" quat="-0.000481092 0.728482 -0.000618967 0.685065" mass="0.608" diaginertia="0.00167218 0.0016161 0.000217621"/>
                <joint name="left_ankle_roll_joint" pos="0 0 0" axis="1 0 0" range="-0.2618 0.2618" actuatorfrcrange="-35 35"/>
                <site name="left_foot" rgba="1 0 0 1" pos="0.04 0 -0.037"/>
                <geom type="mesh" contype="0" conaffinity="0" group="1" density="0" rgba="0.2 0.2 0.2 1" mesh="left_ankle_roll_link"/>
                <geom name="left_foot_box_collision" class="foot_box"/>
                <geom name="left_foot1_collision" class="foot_capsule"
                      fromto="0.1 -0.026 -0.025 0.05 -0.027 -0.025"/>
                <geom name="left_foot2_collision" class="foot_capsule"
                      fromto="-0.045 0 -0.015 0.12 0 -0.015"
                      size="0.02"/>
                <geom name="left_foot3_collision" class="foot_capsule"
                      fromto="0.1 0.026 -0.025 0.05 0.026 -0.025"/>
                <geom size="0.005" pos="-0.05 0.025 -0.03" rgba="0.2 0.2 0.2 1"/>
                <geom size="0.005" pos="-0.05 -0.025 -0.03" rgba="0.2 0.2 0.2 1"/>
                <geom size="0.005" pos="0.12 0.03 -0.03" rgba="0.2 0.2 0.2 1"/>
                <geom size="0.005" pos="0.12 -0.03 -0.03" rgba="0.2 0.2 0.2 1"/>
              </body>
            </body>
          </body>
        </body>
      </body>
    </body>
    <body name="right_hip_pitch_link" pos="0 -0.064452 -0.1027">
      <inertial pos="0.002741 -0.047791 -0.02606" quat="0.954862 -0.293964 0.0302556 -0.030122" mass="1.35" diaginertia="0.00181517 0.00153422 0.00116212"/>
      <joint name="right_hip_pitch_joint" pos="0 0 0" axis="0 1 0" range="-2.5307 2.8798" actuatorfrcrange="-88 88"/>
      <geom type="mesh" contype="0" conaffinity="0" group="1" density="0" rgba="0.2 0.2 0.2 1" mesh="right_hip_pitch_link"/>
      <geom type="mesh" rgba="0.2 0.2 0.2 1" mesh="right_hip_pitch_link"/>
      <body name="right_hip_roll_link" pos="0 -0.052 -0.030465" quat="0.996179 0 -0.0873386 0">
        <inertial pos="0.029812 0.001045 -0.087934" quat="0.977808 1.97119e-05 0.205576 0.0403793" mass="1.52" diaginertia="0.00254986 0.00241169 0.00148755"/>
        <joint name="right_hip_roll_joint" pos="0 0 0" axis="1 0 0" range="-2.9671 0.5236" actuatorfrcrange="-139 139"/>
        <geom type="mesh" contype="0" conaffinity="0" group="1" density="0" rgba="0.7 0.7 0.7 1" mesh="right_hip_roll_link"/>
        <geom type="mesh" rgba="0.7 0.7 0.7 1" mesh="right_hip_roll_link"/>
        <body name="right_hip_yaw_link" pos="0.025001 0 -0.12412">
          <inertial pos="-0.057709 0.010981 -0.15078" quat="0.751181 0.223482 0.15832 0.600598" mass="1.702" diaginertia="0.00776166 0.00717575 0.00160139"/>
          <joint name="right_hip_yaw_joint" pos="0 0 0" axis="0 0 1" range="-2.7576 2.7576" actuatorfrcrange="-88 88"/>
          <geom type="mesh" contype="0" conaffinity="0" group="1" density="0" rgba="0.7 0.7 0.7 1" mesh="right_hip_yaw_link"/>
          <geom type="mesh" rgba="0.7 0.7 0.7 1" mesh="right_hip_yaw_link"/>
          <body name="right_knee_link" pos="-0.078273 -0.0021489 -0.17734" quat="0.996179 0 0.0873386 0">
            <inertial pos="0.005457 -0.003964 -0.12074" quat="0.923439 0.0345276 0.0116333 -0.382012" mass="1.932" diaginertia="0.011374 0.0112843 0.00146452"/>
            <joint name="right_knee_joint" pos="0 0 0" axis="0 1 0" range="-0.087267 2.8798" actuatorfrcrange="-139 139"/>
            <geom type="mesh" contype="0" conaffinity="0" group="1" density="0" rgba="0.7 0.7 0.7 1" mesh="right_knee_link"/>
            <geom type="mesh" rgba="0.7 0.7 0.7 1" mesh="right_knee_link"/>
            <body name="right_ankle_pitch_link" pos="0 9.4445e-05 -0.30001">
              <inertial pos="-0.007269 0 0.011137" quat="0.603053 0.369225 0.369225 0.603053" mass="0.074" diaginertia="1.89e-05 1.40805e-05 6.9195e-06"/>
              <joint name="right_ankle_pitch_joint" pos="0 0 0" axis="0 1 0" range="-0.87267 0.5236" actuatorfrcrange="-35 35"/>
              <geom type="mesh" contype="0" conaffinity="0" group="1" density="0" rgba="0.7 0.7 0.7 1" mesh="right_ankle_pitch_link"/>
              <geom type="mesh" rgba="0.7 0.7 0.7 1" mesh="right_ankle_pitch_link"/>
              <body name="right_ankle_roll_link" pos="0 0 -0.017558">
                <inertial pos="0.026505 0 -0.016425" quat="0.000481092 0.728482 0.000618967 0.685065" mass="0.608" diaginertia="0.00167218 0.0016161 0.000217621"/>
                <joint name="right_ankle_roll_joint" pos="0 0 0" axis="1 0 0" range="-0.2618 0.2618" actuatorfrcrange="-35 35"/>
                <site name="right_foot" rgba="1 0 0 1" pos="0.04 0 -0.037"/>
                <geom type="mesh" contype="0" conaffinity="0" group="1" density="0" rgba="0.2 0.2 0.2 1" mesh="right_ankle_roll_link"/>
                <geom name="right_foot_box_collision" class="foot_box"/>
                <geom name="right_foot1_collision" class="foot_capsule"
                      fromto="0.1 -0.026 -0.025 0.05 -0.026 -0.025"/>
                <geom name="right_foot2_collision" class="foot_capsule"
                      fromto="-0.045 0 -0.015 0.12 0 -0.015"
                      size="0.02"/>
                <geom name="right_foot3_collision" class="foot_capsule"
                      fromto="0.1 0.026 -0.025 0.05 0.026 -0.025"/>
                <geom size="0.005" pos="-0.05 0.025 -0.03" rgba="0.2 0.2 0.2 1"/>
                <geom size="0.005" pos="-0.05 -0.025 -0.03" rgba="0.2 0.2 0.2 1"/>
                <geom size="0.005" pos="0.12 0.03 -0.03" rgba="0.2 0.2 0.2 1"/>
                <geom size="0.005" pos="0.12 -0.03 -0.03" rgba="0.2 0.2 0.2 1"/>
              </body>
            </body>
          </body>
        </body>
      </body>
    </body>
    <body name="waist_yaw_link">
      <inertial pos="0.003494 0.000233 0.018034" quat="0.289697 0.591001 -0.337795 0.672821" mass="0.214" diaginertia="0.000163531 0.000107714 0.000102205"/>
      <joint name="waist_yaw_joint" pos="0 0 0" axis="0 0 1" range="-2.618 2.618" actuatorfrcrange="-88 88"/>
      <geom type="mesh" contype="0" conaffinity="0" group="1" density="0" rgba="0.7 0.7 0.7 1" mesh="waist_yaw_link_rev_1_0"/>
      <body name="waist_roll_link" pos="-0.0039635 0 0.044">
        <inertial pos="0 2.3e-05 0" quat="0.5 0.5 -0.5 0.5" mass="0.086" diaginertia="8.245e-06 7.079e-06 6.339e-06"/>
        <joint name="waist_roll_joint" pos="0 0 0" axis="1 0 0" range="-0.52 0.52" actuatorfrcrange="-35 35"/>
        <geom type="mesh" contype="0" conaffinity="0" group="1" density="0" rgba="0.7 0.7 0.7 1" mesh="waist_roll_link_rev_1_0"/>
        <body name="torso_link">
          <inertial pos="0.00203158 0.000339683 0.184567" quat="0.999803 -6.03494e-05 0.0198245 0.00131986" mass="7.818" diaginertia="0.121852 0.10983 0.0273736"/>
          <joint name="waist_pitch_joint" pos="0 0 0" axis="0 1 0" range="-0.52 0.52" actuatorfrcrange="-35 35"/>
          <site name="imu_in_torso" size="0.01" pos="-0.03959 -0.00224 0.14792"/>
          <site name="chest" size="0.01" pos="0.0 0.0 0.24778"/>
          <geom type="mesh" contype="0" conaffinity="0" group="1" density="0" rgba="0.7 0.7 0.7 1" mesh="torso_link_rev_1_0"/>
          <geom type="mesh" rgba="0.7 0.7 0.7 1" mesh="torso_link_rev_1_0"/>
          <geom pos="0.0039635 0 -0.044" quat="1 0 0 0" type="mesh" contype="0" conaffinity="0" group="1" density="0" rgba="0.2 0.2 0.2 1" mesh="logo_link"/>
          <geom pos="0.0039635 0 -0.044" quat="1 0 0 0" type="mesh" rgba="0.2 0.2 0.2 1" mesh="logo_link"/>
          <geom pos="0.0039635 0 -0.044" type="mesh" contype="0" conaffinity="0" group="1" density="0" rgba="0.2 0.2 0.2 1" mesh="head_link"/>
          <geom pos="0.0039635 0 -0.044" type="mesh" rgba="0.2 0.2 0.2 1" mesh="head_link"/>
          <geom pos="0.0039635 0 -0.054" quat="1 0 0 0" type="mesh" contype="0" conaffinity="0" group="1" density="0" rgba="0.7 0.7 0.7 1" mesh="waist_support_link"/>
          <geom pos="0.0039635 0 -0.054" quat="1 0 0 0" type="mesh" rgba="0.7 0.7 0.7 1" mesh="waist_support_link"/>
          <body name="left_shoulder_pitch_link" pos="0.0039563 0.10022 0.24778" quat="0.990264 0.139201 1.38722e-05 -9.86868e-05">
            <inertial pos="0 0.035892 -0.011628" quat="0.654152 0.0130458 -0.326267 0.68225" mass="0.718" diaginertia="0.000465864 0.000432842 0.000406394"/>
            <joint name="left_shoulder_pitch_joint" pos="0 0 0" axis="0 1 0" range="-3.0892 2.6704" actuatorfrcrange="-25 25"/>
            <geom type="mesh" contype="0" conaffinity="0" group="1" density="0" rgba="0.7 0.7 0.7 1" mesh="left_shoulder_pitch_link"/>
            <geom size="0.03 0.025" pos="0 0.04 -0.01" quat="0.707107 0 0.707107 0" type="cylinder" rgba="0.7 0.7 0.7 1"/>
            <body name="left_shoulder_roll_link" pos="0 0.038 -0.013831" quat="0.990268 -0.139172 0 0">
              <inertial pos="-0.000227 0.00727 -0.063243" quat="0.701256 -0.0196223 -0.00710317 0.712604" mass="0.643" diaginertia="0.000691311 0.000618011 0.000388977"/>
              <joint name="left_shoulder_roll_joint" pos="0 0 0" axis="1 0 0" range="-1.5882 2.2515" actuatorfrcrange="-25 25"/>
              <geom type="mesh" contype="0" conaffinity="0" group="1" density="0" rgba="0.7 0.7 0.7 1" mesh="left_shoulder_roll_link"/>
              <geom size="0.03 0.015" pos="-0.004 0.006 -0.053" type="cylinder" rgba="0.7 0.7 0.7 1"/>
              <body name="left_shoulder_yaw_link" pos="0 0.00624 -0.1032">
                <inertial pos="0.010773 -0.002949 -0.072009" quat="0.716879 -0.0964829 -0.0679942 0.687134" mass="0.734" diaginertia="0.00106187 0.00103217 0.000400661"/>
                <joint name="left_shoulder_yaw_joint" pos="0 0 0" axis="0 0 1" range="-2.618 2.618" actuatorfrcrange="-25 25"/>
                <geom type="mesh" contype="0" conaffinity="0" group="1" density="0" rgba="0.7 0.7 0.7 1" mesh="left_shoulder_yaw_link"/>
                <geom type="mesh" rgba="0.7 0.7 0.7 1" mesh="left_shoulder_yaw_link"/>
                <body name="left_elbow_link" pos="0.015783 0 -0.080518">
                  <inertial pos="0.064956 0.004454 -0.010062" quat="0.541765 0.636132 0.388821 0.388129" mass="0.6" diaginertia="0.000443035 0.000421612 0.000259353"/>
                  <joint name="left_elbow_joint" pos="0 0 0" axis="0 1 0" range="-1.0472 2.0944" actuatorfrcrange="-25 25"/>
                  <geom type="mesh" contype="0" conaffinity="0" group="1" density="0" rgba="0.7 0.7 0.7 1" mesh="left_elbow_link"/>
                  <geom type="mesh" rgba="0.7 0.7 0.7 1" mesh="left_elbow_link"/>
                  <body name="left_wrist_roll_link" pos="0.1 0.00188791 -0.01">
                    <inertial pos="0.0171394 0.000537591 4.8864e-07" quat="0.575338 0.411667 -0.574906 0.411094" mass="0.085445" diaginertia="5.48211e-05 4.96646e-05 3.57798e-05"/>
                    <joint name="left_wrist_roll_joint" pos="0 0 0" axis="1 0 0" range="-1.97222 1.97222" actuatorfrcrange="-25 25"/>
                    <geom type="mesh" contype="0" conaffinity="0" group="1" density="0" rgba="0.7 0.7 0.7 1" mesh="left_wrist_roll_link"/>
                    <geom type="mesh" rgba="0.7 0.7 0.7 1" mesh="left_wrist_roll_link"/>
                    <body name="left_wrist_pitch_link" pos="0.038 0 0">
                      <inertial pos="0.0229999 -0.00111685 -0.00111658" quat="0.249998 0.661363 0.293036 0.643608" mass="0.48405" diaginertia="0.000430353 0.000429873 0.000164648"/>
                      <joint name="left_wrist_pitch_joint" pos="0 0 0" axis="0 1 0" range="-1.61443 1.61443" actuatorfrcrange="-5 5"/>
                      <geom type="mesh" contype="0" conaffinity="0" group="1" density="0" rgba="0.7 0.7 0.7 1" mesh="left_wrist_pitch_link"/>
                      <geom type="mesh" rgba="0.7 0.7 0.7 1" mesh="left_wrist_pitch_link"/>
                      <body name="left_wrist_yaw_link" pos="0.046 0 0">
                        <inertial pos="0.0736653 0.00366142 -0.000906332" quat="0.475616 0.494432 0.524277 0.50444" mass="0.322576" diaginertia="0.000389321 0.000362364 5.76718e-05"/>
                        <joint name="left_wrist_yaw_joint" pos="0 0 0" axis="0 0 1" range="-1.61443 1.61443" actuatorfrcrange="-5 5"/>
                        <geom type="mesh" contype="0" conaffinity="0" group="1" density="0" rgba="0.7 0.7 0.7 1" mesh="left_wrist_yaw_link"/>
                        <geom type="mesh" rgba="0.7 0.7 0.7 1" mesh="left_wrist_yaw_link"/>
                        <geom pos="0.0415 0 0" quat="0.5 -0.5 0.5 -0.5" type="mesh" contype="0" conaffinity="0" group="1" density="0" rgba="1 1 1 1" mesh="left_base_link"/>
                        <geom pos="0.0415 0 0" quat="0.5 -0.5 0.5 -0.5" type="mesh" rgba="1 1 1 1" mesh="left_base_link"/>
                        <body name="left_thumb_metacarpal_Link" pos="0.069325 -0.0045 0.019" quat="0.540158 -0.456322 0.540158 -0.456322">
                          <inertial pos="1.52304e-05 -0.0070724 -0.0042084" quat="0.882814 0.0586739 -0.0302438 0.465061" mass="0.01" diaginertia="1.66114e-07 1.56005e-07 4.93864e-08"/>
                          <joint name="left_thumb_metacarpal_joint" pos="0 0 0" axis="0 0 1" range="0 1.5184" actuatorfrcrange="-0.5 0.5"/>
                          <geom type="mesh" contype="0" conaffinity="0" group="1" density="0" rgba="1 1 1 1" mesh="left_thumb_metacarpal_Link"/>
                          <geom type="mesh" rgba="1 1 1 1" mesh="left_thumb_metacarpal_Link"/>
                          <body name="left_thumb_proximal_Link" pos="0 -0.014227 0" quat="0.0726364 0.124805 0.0765192 0.986556">
                            <inertial pos="3.41002e-07 0.0250091 -0.00175057" quat="0.504397 0.495535 -0.495534 0.504455" mass="0.05" diaginertia="3.40018e-06 3.23319e-06 5.63592e-07"/>
                            <joint name="left_thumb_proximal_joint" pos="0 0 0" axis="1 0 0" range="0 1.0472" actuatorfrcrange="-1.1 1.1"/>
                            <geom type="mesh" contype="0" conaffinity="0" group="1" density="0" rgba="1 1 1 1" mesh="left_thumb_proximal_Link"/>
                            <geom type="mesh" rgba="1 1 1 1" mesh="left_thumb_proximal_Link"/>
                            <body name="left_thumb_distal_Link" pos="0 0.052 0">
                              <inertial pos="-1.65619e-07 0.0117551 1.13666e-05" quat="0.528503 0.469771 -0.469581 0.528672" mass="0.01" diaginertia="2.21049e-07 1.67809e-07 1.13875e-07"/>
                              <joint name="left_thumb_distal_joint" pos="0 0 0" axis="1 0 0" range="0 1.0472" actuatorfrcrange="-1.1 1.1"/>
                              <geom type="mesh" contype="0" conaffinity="0" group="1" density="0" rgba="1 1 1 1" mesh="left_thumb_distal_Link"/>
                              <geom type="mesh" rgba="1 1 1 1" mesh="left_thumb_distal_Link"/>
                              <body name="left_thumb_tip_Link" pos="0 0.0265288 -0.00177344" quat="0 0 0.033369 0.999443">
                                <inertial pos="0 0 0" mass="0.001" diaginertia="0.001 0.001 0.001"/>
                                <joint name="left_thumb_tip_joint" pos="0 0 0" axis="-1 0 0" range="-0.001 0.001"/>
                                <geom type="mesh" contype="0" conaffinity="0" group="1" density="0" rgba="1 1 1 1" mesh="left_thumb_tip_Link"/>
                                <geom type="mesh" rgba="1 1 1 1" mesh="left_thumb_tip_Link"/>
                              </body>
                            </body>
                          </body>
                        </body>
                        <body name="left_index_proximal_Link" pos="0.122376 0.0021349 0.029578" quat="0.524171 -0.389611 0.550255 -0.520257">
                          <inertial pos="-0.00223539 -3.80545e-06 0.0176439" mass="0.009" diaginertia="0.001 0.001 0.001"/>
                          <joint name="left_index_proximal_joint" pos="0 0 0" axis="0 1 0" range="0 1.4661" actuatorfrcrange="-2 2"/>
                          <geom type="mesh" contype="0" conaffinity="0" group="1" density="0" rgba="1 1 1 1" mesh="left_index_proximal_Link"/>
                          <geom type="mesh" rgba="1 1 1 1" mesh="left_index_proximal_Link"/>
                          <body name="left_index_distal_Link" pos="0 0 0.032">
                            <inertial pos="0.00487463 -7.61037e-08 0.0174016" quat="0.986653 -1.93906e-06 0.162839 3.20026e-07" mass="0.01" diaginertia="0.00200042 0.00200042 0.002"/>
                            <joint name="left_index_distal_joint" pos="0 0 0" axis="0 1 0" range="0 1.693" actuatorfrcrange="-2 2"/>
                            <geom type="mesh" contype="0" conaffinity="0" group="1" density="0" rgba="1 1 1 1" mesh="left_index_distal_Link"/>
                            <geom type="mesh" rgba="1 1 1 1" mesh="left_index_distal_Link"/>
                            <geom pos="0.011097 0 0.035739" quat="0.970472 0 0.241212 0" type="mesh" contype="0" conaffinity="0" group="1" density="0" rgba="1 1 1 1" mesh="left_index_tip_Link"/>
                            <geom pos="0.011097 0 0.035739" quat="0.970472 0 0.241212 0" type="mesh" rgba="1 1 1 1" mesh="left_index_tip_Link"/>
                          </body>
                        </body>
                        <body name="left_middle_proximal_Link" pos="0.126493 0.0045935 0.010061" quat="0.483518 -0.438557 0.540601 -0.530687">
                          <inertial pos="-0.00222419 -3.61991e-06 0.020305" mass="0.009" diaginertia="0.001 0.001 0.001"/>
                          <joint name="left_middle_proximal_joint" pos="0 0 0" axis="0 1 0" range="0 1.4661" actuatorfrcrange="-2 2"/>
                          <geom type="mesh" contype="0" conaffinity="0" group="1" density="0" rgba="1 1 1 1" mesh="left_middle_proximal_Link"/>
                          <geom type="mesh" rgba="1 1 1 1" mesh="left_middle_proximal_Link"/>
                          <body name="left_middle_distal_Link" pos="0 0 0.037" quat="0.997999 0 0.0632278 0">
                            <inertial pos="0.00316309 2.94489e-07 0.0206472" quat="0.99518 6.8255e-06 0.0980637 -6.72575e-07" mass="0.01" diaginertia="0.00200051 0.00200051 0.002"/>
                            <joint name="left_middle_distal_joint" pos="0 0 0" axis="0 1 0" range="0 1.693" actuatorfrcrange="-2 2"/>
                            <geom type="mesh" contype="0" conaffinity="0" group="1" density="0" rgba="1 1 1 1" mesh="left_middle_distal_Link"/>
                            <geom type="mesh" rgba="1 1 1 1" mesh="left_middle_distal_Link"/>
                            <geom pos="0.0073534 0 0.041703" quat="0.984807 0 0.17365 0" type="mesh" contype="0" conaffinity="0" group="1" density="0" rgba="1 1 1 1" mesh="left_middle_tip_Link"/>
                            <geom pos="0.0073534 0 0.041703" quat="0.984807 0 0.17365 0" type="mesh" rgba="1 1 1 1" mesh="left_middle_tip_Link"/>
                          </body>
                        </body>
                        <body name="left_ring_proximal_Link" pos="0.125482 0.00468768 -0.0100263" quat="0.438847 -0.483813 0.530448 -0.540337">
                          <inertial pos="-0.00234461 -5.32058e-06 0.0191786" mass="0.009" diaginertia="0.001 0.001 0.001"/>
                          <joint name="left_ring_proximal_joint" pos="0 0 0" axis="0 1 0" range="0 1.4661" actuatorfrcrange="-2 2"/>
                          <geom type="mesh" contype="0" conaffinity="0" group="1" density="0" rgba="1 1 1 1" mesh="left_ring_proximal_Link"/>
                          <geom type="mesh" rgba="1 1 1 1" mesh="left_ring_proximal_Link"/>
                          <body name="left_ring_distal_Link" pos="0 0 0.035" quat="0.997999 0 0.0632278 0">
                            <inertial pos="0.0029668 -2.51097e-08 0.0200084" quat="0.994971 0 0.100163 0" mass="0.01" diaginertia="0.0020005 0.0020005 0.002"/>
                            <joint name="left_ring_distal_joint" pos="0 0 0" axis="0 1 0" range="0 1.693" actuatorfrcrange="-2 2"/>
                            <geom type="mesh" contype="0" conaffinity="0" group="1" density="0" rgba="1 1 1 1" mesh="left_ring_distal_Link"/>
                            <geom type="mesh" rgba="1 1 1 1" mesh="left_ring_distal_Link"/>
                            <geom pos="0.0071824 0 0.040734" quat="0.984807 0 0.17365 0" type="mesh" contype="0" conaffinity="0" group="1" density="0" rgba="1 1 1 1" mesh="left_ring_tip_Link"/>
                            <geom pos="0.0071824 0 0.040734" quat="0.984807 0 0.17365 0" type="mesh" rgba="1 1 1 1" mesh="left_ring_tip_Link"/>
                          </body>
                        </body>
                        <body name="left_pinky_proximal_Link" pos="0.120194 0.0023733 -0.029356" quat="0.390269 -0.52487 0.519763 -0.549589">
                          <inertial pos="-0.00213267 -7.0226e-06 0.016068" mass="0.009" diaginertia="0.001 0.001 0.001"/>
                          <joint name="left_pinky_proximal_joint" pos="0 0 0" axis="0 1 0" range="0 1.4661" actuatorfrcrange="-2 2"/>
                          <geom type="mesh" contype="0" conaffinity="0" group="1" density="0" rgba="1 1 1 1" mesh="left_pinky_proximal_Link"/>
                          <geom type="mesh" rgba="1 1 1 1" mesh="left_pinky_proximal_Link"/>
                          <body name="left_pinky_distal_Link" pos="0 0 0.029">
                            <inertial pos="0.00460916 -7.27697e-08 0.0159878" quat="0.987222 -2.0139e-06 0.159354 3.25076e-07" mass="0.01" diaginertia="0.00200035 0.00200035 0.002"/>
                            <joint name="left_pinky_distal_joint" pos="0 0 0" axis="0 1 0" range="0 1.693" actuatorfrcrange="-2 2"/>
                            <geom type="mesh" contype="0" conaffinity="0" group="1" density="0" rgba="1 1 1 1" mesh="left_pinky_distal_Link"/>
                            <geom type="mesh" rgba="1 1 1 1" mesh="left_pinky_distal_Link"/>
                            <geom pos="0.010221 0 0.032918" quat="0.971859 0 0.235565 0" type="mesh" contype="0" conaffinity="0" group="1" density="0" rgba="1 1 1 1" mesh="left_pinky_tip_Link"/>
                            <geom pos="0.010221 0 0.032918" quat="0.971859 0 0.235565 0" type="mesh" rgba="1 1 1 1" mesh="left_pinky_tip_Link"/>
                          </body>
                        </body>
                      </body>
                    </body>
                  </body>
                </body>
              </body>
            </body>
          </body>
          <body name="right_shoulder_pitch_link" pos="0.0039563 -0.10021 0.24778" quat="0.990264 -0.139201 1.38722e-05 9.86868e-05">
            <inertial pos="0 -0.035892 -0.011628" quat="0.68225 -0.326267 0.0130458 0.654152" mass="0.718" diaginertia="0.000465864 0.000432842 0.000406394"/>
            <joint name="right_shoulder_pitch_joint" pos="0 0 0" axis="0 1 0" range="-3.0892 2.6704" actuatorfrcrange="-25 25"/>
            <geom type="mesh" contype="0" conaffinity="0" group="1" density="0" rgba="0.7 0.7 0.7 1" mesh="right_shoulder_pitch_link"/>
            <geom size="0.03 0.025" pos="0 -0.04 -0.01" quat="0.707107 0 0.707107 0" type="cylinder" rgba="0.7 0.7 0.7 1"/>
            <body name="right_shoulder_roll_link" pos="0 -0.038 -0.013831" quat="0.990268 0.139172 0 0">
              <inertial pos="-0.000227 -0.00727 -0.063243" quat="0.712604 -0.00710317 -0.0196223 0.701256" mass="0.643" diaginertia="0.000691311 0.000618011 0.000388977"/>
              <joint name="right_shoulder_roll_joint" pos="0 0 0" axis="1 0 0" range="-2.2515 1.5882" actuatorfrcrange="-25 25"/>
              <geom type="mesh" contype="0" conaffinity="0" group="1" density="0" rgba="0.7 0.7 0.7 1" mesh="right_shoulder_roll_link"/>
              <geom size="0.03 0.015" pos="-0.004 -0.006 -0.053" type="cylinder" rgba="0.7 0.7 0.7 1"/>
              <body name="right_shoulder_yaw_link" pos="0 -0.00624 -0.1032">
                <inertial pos="0.010773 0.002949 -0.072009" quat="0.687134 -0.0679942 -0.0964829 0.716879" mass="0.734" diaginertia="0.00106187 0.00103217 0.000400661"/>
                <joint name="right_shoulder_yaw_joint" pos="0 0 0" axis="0 0 1" range="-2.618 2.618" actuatorfrcrange="-25 25"/>
                <geom type="mesh" contype="0" conaffinity="0" group="1" density="0" rgba="0.7 0.7 0.7 1" mesh="right_shoulder_yaw_link"/>
                <geom type="mesh" rgba="0.7 0.7 0.7 1" mesh="right_shoulder_yaw_link"/>
                <body name="right_elbow_link" pos="0.015783 0 -0.080518">
                  <inertial pos="0.064956 -0.004454 -0.010062" quat="0.388129 0.388821 0.636132 0.541765" mass="0.6" diaginertia="0.000443035 0.000421612 0.000259353"/>
                  <joint name="right_elbow_joint" pos="0 0 0" axis="0 1 0" range="-1.0472 2.0944" actuatorfrcrange="-25 25"/>
                  <geom type="mesh" contype="0" conaffinity="0" group="1" density="0" rgba="0.7 0.7 0.7 1" mesh="right_elbow_link"/>
                  <geom type="mesh" rgba="0.7 0.7 0.7 1" mesh="right_elbow_link"/>
                  <body name="right_wrist_roll_link" pos="0.1 -0.00188791 -0.01">
                    <inertial pos="0.0171394 -0.000537591 4.8864e-07" quat="0.411667 0.575338 -0.411094 0.574906" mass="0.085445" diaginertia="5.48211e-05 4.96646e-05 3.57798e-05"/>
                    <joint name="right_wrist_roll_joint" pos="0 0 0" axis="1 0 0" range="-1.97222 1.97222" actuatorfrcrange="-25 25"/>
                    <geom type="mesh" contype="0" conaffinity="0" group="1" density="0" rgba="0.7 0.7 0.7 1" mesh="right_wrist_roll_link"/>
                    <geom type="mesh" rgba="0.7 0.7 0.7 1" mesh="right_wrist_roll_link"/>
                    <body name="right_wrist_pitch_link" pos="0.038 0 0">
                      <inertial pos="0.0229999 0.00111685 -0.00111658" quat="0.643608 0.293036 0.661363 0.249998" mass="0.48405" diaginertia="0.000430353 0.000429873 0.000164648"/>
                      <joint name="right_wrist_pitch_joint" pos="0 0 0" axis="0 1 0" range="-1.61443 1.61443" actuatorfrcrange="-5 5"/>
                      <geom type="mesh" contype="0" conaffinity="0" group="1" density="0" rgba="0.7 0.7 0.7 1" mesh="right_wrist_pitch_link"/>
                      <geom type="mesh" rgba="0.7 0.7 0.7 1" mesh="right_wrist_pitch_link"/>
                      <body name="right_wrist_yaw_link" pos="0.046 0 0">
                        <inertial pos="0.0736615 -0.00365065 -0.000918885" quat="0.505367 0.524057 0.497401 0.471763" mass="0.322576" diaginertia="0.00136703 0.0013469 0.00104894"/>
                        <joint name="right_wrist_yaw_joint" pos="0 0 0" axis="0 0 1" range="-1.61443 1.61443" actuatorfrcrange="-5 5"/>
                        <geom type="mesh" contype="0" conaffinity="0" group="1" density="0" rgba="0.7 0.7 0.7 1" mesh="right_wrist_yaw_link"/>
                        <geom type="mesh" rgba="0.7 0.7 0.7 1" mesh="right_wrist_yaw_link"/>
                        <geom pos="0.0415 0 0" quat="0.5 0.5 0.5 0.5" type="mesh" contype="0" conaffinity="0" group="1" density="0" rgba="1 1 1 1" mesh="right_base_link"/>
                        <geom pos="0.0415 0 0" quat="0.5 0.5 0.5 0.5" type="mesh" rgba="1 1 1 1" mesh="right_base_link"/>
                        <body name="right_thumb_metacarpal_link" pos="0.069325 0.005619 0.019867" quat="-0.542436 -0.453611 0.54244 0.453607">
                          <inertial pos="-1.51106e-05 0.00707243 0.00420847" mass="0.01" diaginertia="0.001 0.001 0.001"/>
                          <joint name="right_thumb_metacarpal_joint" pos="0 0 0" axis="0 0 1" range="0 1.5184" actuatorfrcrange="-0.5 0.5"/>
                          <geom type="mesh" contype="0" conaffinity="0" group="1" density="0" rgba="1 1 1 1" mesh="right_thumb_metacarpal_link"/>
                          <geom type="mesh" rgba="1 1 1 1" mesh="right_thumb_metacarpal_link"/>
                          <body name="right_thumb_proximal_link" pos="0 0.014227 0" quat="0.124805 -0.0726357 -0.986555 0.0765254">
                            <inertial pos="-4.57221e-07 0.025009 -0.00175049" mass="0.05" diaginertia="0.001 0.001 0.001"/>
                            <joint name="right_thumb_proximal_joint" pos="0 0 0" axis="1 0 0" range="0 1.0472" actuatorfrcrange="-1.1 1.1"/>
                            <geom type="mesh" contype="0" conaffinity="0" group="1" density="0" rgba="1 1 1 1" mesh="right_thumb_proximal_link"/>
                            <geom type="mesh" rgba="1 1 1 1" mesh="right_thumb_proximal_link"/>
                            <body name="right_thumb_distal_link" pos="0 0.052 0">
                              <inertial pos="-5.88258e-09 0.0117545 1.13324e-05" mass="0.01" diaginertia="0.001 0.001 0.001"/>
                              <joint name="right_thumb_distal_joint" pos="0 0 0" axis="1 0 0" range="0 1.0472" actuatorfrcrange="-1.1 1.1"/>
                              <geom type="mesh" contype="0" conaffinity="0" group="1" density="0" rgba="1 1 1 1" mesh="right_thumb_distal_link"/>
                              <geom type="mesh" rgba="1 1 1 1" mesh="right_thumb_distal_link"/>
                              <body name="right_thumb_tip" pos="0 0.026529 -0.0017734" quat="0.999443 -0.0333688 0 0">
                                <inertial pos="0 -8.79922e-05 0" mass="0.001" diaginertia="0.001 0.001 0.001"/>
                                <joint name="right_thumb_tip_joint" pos="0 0 0" axis="1 0 0" range="-0.001 0.001"/>
                                <geom type="mesh" contype="0" conaffinity="0" group="1" density="0" rgba="1 1 1 1" mesh="right_thumb_tip"/>
                                <geom type="mesh" rgba="1 1 1 1" mesh="right_thumb_tip"/>
                              </body>
                            </body>
                          </body>
                        </body>
                        <body name="right_index_proximal_link" pos="0.122376 -0.0021181 0.029568" quat="0.524171 0.389611 0.550255 0.520257">
                          <inertial pos="-0.00223495 3.15875e-06 0.0176402" mass="0.009" diaginertia="0.001 0.001 0.001"/>
                          <joint name="right_index_proximal_joint" pos="0 0 0" axis="0 1 0" range="0 1.4661" actuatorfrcrange="-2 2"/>
                          <geom type="mesh" contype="0" conaffinity="0" group="1" density="0" rgba="1 1 1 1" mesh="right_index_proximal_link"/>
                          <geom type="mesh" rgba="1 1 1 1" mesh="right_index_proximal_link"/>
                          <body name="right_index_distal_link" pos="0 0 0.032">
                            <inertial pos="0.00487477 1.04787e-07 0.0174018" quat="0.986653 2.66959e-06 0.162837 -4.40589e-07" mass="0.01" diaginertia="0.00200042 0.00200042 0.002"/>
                            <joint name="right_index_distal_joint" pos="0 0 0" axis="0 1 0" range="0 1.693" actuatorfrcrange="-2 2"/>
                            <geom type="mesh" contype="0" conaffinity="0" group="1" density="0" rgba="1 1 1 1" mesh="right_index_distal_link"/>
                            <geom type="mesh" rgba="1 1 1 1" mesh="right_index_distal_link"/>
                            <geom pos="0.011097 0 0.035739" quat="0.971859 0 0.235565 0" type="mesh" contype="0" conaffinity="0" group="1" density="0" rgba="1 1 1 1" mesh="right_index_tip"/>
                            <geom pos="0.011097 0 0.035739" quat="0.971859 0 0.235565 0" type="mesh" rgba="1 1 1 1" mesh="right_index_tip"/>
                          </body>
                        </body>
                        <body name="right_middle_proximal_link" pos="0.126493 -0.0045767 0.010051" quat="0.483518 0.438557 0.540601 0.530687">
                          <inertial pos="-0.00222511 5.25632e-06 0.0203008" mass="0.009" diaginertia="0.001 0.001 0.001"/>
                          <joint name="right_middle_proximal_joint" pos="0 0 0" axis="0 1 0" range="0 1.4661" actuatorfrcrange="-2 2"/>
                          <geom type="mesh" contype="0" conaffinity="0" group="1" density="0" rgba="1 1 1 1" mesh="right_middle_proximal_link"/>
                          <geom type="mesh" rgba="1 1 1 1" mesh="right_middle_proximal_link"/>
                          <body name="right_middle_distal_link" pos="0 0 0.037">
                            <inertial pos="0.00574351 2.8872e-07 0.0200831" quat="0.986987 6.63658e-06 0.160797 -1.08121e-06" mass="0.01" diaginertia="0.00200051 0.00200051 0.002"/>
                            <joint name="right_middle_distal_joint" pos="0 0 0" axis="0 1 0" range="0 1.693" actuatorfrcrange="-2 2"/>
                            <geom type="mesh" contype="0" conaffinity="0" group="1" density="0" rgba="1 1 1 1" mesh="right_middle_distal_link"/>
                            <geom type="mesh" rgba="1 1 1 1" mesh="right_middle_distal_link"/>
                            <geom pos="0.012558 0 0.040442" quat="0.971859 0 0.235565 0" type="mesh" contype="0" conaffinity="0" group="1" density="0" rgba="1 1 1 1" mesh="right_middle_tip"/>
                            <geom pos="0.012558 0 0.040442" quat="0.971859 0 0.235565 0" type="mesh" rgba="1 1 1 1" mesh="right_middle_tip"/>
                          </body>
                        </body>
                        <body name="right_ring_proximal_link" pos="0.125482 -0.0046709 -0.010037" quat="0.438846 0.483813 0.530448 0.540337">
                          <inertial pos="-0.00234495 5.87955e-06 0.0191774" mass="0.009" diaginertia="0.001 0.001 0.001"/>
                          <joint name="right_ring_proximal_joint" pos="0 0 0" axis="0 1 0" range="0 1.4661" actuatorfrcrange="-2 2"/>
                          <geom type="mesh" contype="0" conaffinity="0" group="1" density="0" rgba="1 1 1 1" mesh="right_ring_proximal_link"/>
                          <geom type="mesh" rgba="1 1 1 1" mesh="right_ring_proximal_link"/>
                          <body name="right_ring_distal_link" pos="0 0 0.035">
                            <inertial pos="0.00546814 -2.17666e-08 0.0194739" quat="0.986645 0 0.162886 0" mass="0.01" diaginertia="0.0020005 0.0020005 0.002"/>
                            <joint name="right_ring_distal_joint" pos="0 0 0" axis="0 1 0" range="0 1.693" actuatorfrcrange="-2 2"/>
                            <geom type="mesh" contype="0" conaffinity="0" group="1" density="0" rgba="1 1 1 1" mesh="right_ring_distal_link"/>
                            <geom type="mesh" rgba="1 1 1 1" mesh="right_ring_distal_link"/>
                            <geom pos="0.012266 0 0.039501" quat="0.971859 0 0.235565 0" type="mesh" contype="0" conaffinity="0" group="1" density="0" rgba="1 1 1 1" mesh="right_ring_tip"/>
                            <geom pos="0.012266 0 0.039501" quat="0.971859 0 0.235565 0" type="mesh" rgba="1 1 1 1" mesh="right_ring_tip"/>
                          </body>
                        </body>
                        <body name="right_pinky_proximal_link" pos="0.120194 -0.0023566 -0.029366" quat="0.390269 0.52487 0.519763 0.549589">
                          <inertial pos="-0.00213212 7.75039e-06 0.0160672" mass="0.009" diaginertia="0.001 0.001 0.001"/>
                          <joint name="right_pinky_proximal_joint" pos="0 0 0" axis="0 1 0" range="0 1.4661" actuatorfrcrange="-2 2"/>
                          <geom type="mesh" contype="0" conaffinity="0" group="1" density="0" rgba="1 1 1 1" mesh="right_pinky_proximal_link"/>
                          <geom type="mesh" rgba="1 1 1 1" mesh="right_pinky_proximal_link"/>
                          <body name="right_pinky_distal_link" pos="0 0 0.029">
                            <inertial pos="0.00460928 -1.0686e-07 0.0159884" quat="0.987221 -2.95744e-06 0.159356 4.77387e-07" mass="0.01" diaginertia="0.00200035 0.00200035 0.002"/>
                            <joint name="right_pinky_distal_joint" pos="0 0 0" axis="0 1 0" range="0 1.693" actuatorfrcrange="-2 2"/>
                            <geom type="mesh" contype="0" conaffinity="0" group="1" density="0" rgba="1 1 1 1" mesh="right_pinky_distal_link"/>
                            <geom type="mesh" rgba="1 1 1 1" mesh="right_pinky_distal_link"/>
                            <geom pos="0.010221 0 0.032918" quat="0.971859 0 0.235565 0" type="mesh" contype="0" conaffinity="0" group="1" density="0" rgba="1 1 1 1" mesh="right_pinky_tip"/>
                            <geom pos="0.010221 0 0.032918" quat="0.971859 0 0.235565 0" type="mesh" rgba="1 1 1 1" mesh="right_pinky_tip"/>
                          </body>
                        </body>
                      </body>
                    </body>
                  </body>
                </body>
              </body>
            </body>
          </body>
        </body>
      </body>
    </body>
    </body>
  </worldbody>

  <actuator>
    <motor class="hip_pitch" name="left_hip_pitch_joint" joint="left_hip_pitch_joint"/>
    <motor class="hip_roll" name="left_hip_roll_joint" joint="left_hip_roll_joint"/>
    <motor class="hip_yaw" name="left_hip_yaw_joint" joint="left_hip_yaw_joint"/>
    <motor class="knee" name="left_knee_joint" joint="left_knee_joint"/>
    <motor class="ankle_pitch" name="left_ankle_pitch_joint" joint="left_ankle_pitch_joint"/>
    <motor class="ankle_roll" name="left_ankle_roll_joint" joint="left_ankle_roll_joint"/>

    <motor class="hip_pitch" name="right_hip_pitch_joint" joint="right_hip_pitch_joint"/>
    <motor class="hip_roll" name="right_hip_roll_joint" joint="right_hip_roll_joint"/>
    <motor class="hip_yaw" name="right_hip_yaw_joint" joint="right_hip_yaw_joint"/>
    <motor class="knee" name="right_knee_joint" joint="right_knee_joint"/>
    <motor class="ankle_pitch" name="right_ankle_pitch_joint" joint="right_ankle_pitch_joint"/>
    <motor class="ankle_roll" name="right_ankle_roll_joint" joint="right_ankle_roll_joint"/>

    <motor class="waist_yaw" name="waist_yaw_joint" joint="waist_yaw_joint"/>
    <motor class="waist_roll" name="waist_roll_joint" joint="waist_roll_joint"/>
    <motor class="waist_pitch" name="waist_pitch_joint" joint="waist_pitch_joint"/>

    <motor class="shoulder_pitch" name="left_shoulder_pitch_joint" joint="left_shoulder_pitch_joint"/>
    <motor class="shoulder_roll" name="left_shoulder_roll_joint" joint="left_shoulder_roll_joint"/>
    <motor class="shoulder_yaw" name="left_shoulder_yaw_joint" joint="left_shoulder_yaw_joint"/>
    <motor class="elbow" name="left_elbow_joint" joint="left_elbow_joint"/>
    <motor class="wrist_roll" name="left_wrist_roll_joint" joint="left_wrist_roll_joint"/>
    <motor class="wrist_pitch" name="left_wrist_pitch_joint" joint="left_wrist_pitch_joint"/>
    <motor class="wrist_yaw" name="left_wrist_yaw_joint" joint="left_wrist_yaw_joint"/>

    <motor class="shoulder_pitch" name="right_shoulder_pitch_joint" joint="right_shoulder_pitch_joint"/>
    <motor class="shoulder_roll" name="right_shoulder_roll_joint" joint="right_shoulder_roll_joint"/>
    <motor class="shoulder_yaw" name="right_shoulder_yaw_joint" joint="right_shoulder_yaw_joint"/>
    <motor class="elbow" name="right_elbow_joint" joint="right_elbow_joint"/>
    <motor class="wrist_roll" name="right_wrist_roll_joint" joint="right_wrist_roll_joint"/>
    <motor class="wrist_pitch" name="right_wrist_pitch_joint" joint="right_wrist_pitch_joint"/>
    <motor class="wrist_yaw" name="right_wrist_yaw_joint" joint="right_wrist_yaw_joint"/>
  </actuator>

  <sensor>
    <velocimeter site="imu_in_torso" name="local_linvel_torso"/>
    <velocimeter site="imu_in_pelvis" name="local_linvel_pelvis"/>
    <accelerometer site="imu_in_torso" name="accelerometer_torso"/>
    <accelerometer site="imu_in_pelvis" name="accelerometer_pelvis"/>
    <gyro site="imu_in_torso" name="gyro_torso"/>
    <gyro site="imu_in_pelvis" name="gyro_pelvis"/>
    <framezaxis objtype="site" objname="imu_in_torso" name="upvector_torso"/>
    <framezaxis objtype="site" objname="imu_in_pelvis" name="upvector_pelvis"/>
    <framequat objtype="site" objname="imu_in_torso" name="orientation_torso"/>
    <framequat objtype="site" objname="imu_in_pelvis" name="orientation_pelvis"/>
    <framelinvel objtype="site" objname="imu_in_torso" name="global_linvel_torso"/>
    <framelinvel objtype="site" objname="imu_in_pelvis" name="global_linvel_pelvis"/>
    <frameangvel objtype="site" objname="imu_in_torso" name="global_angvel_torso"/>
    <frameangvel objtype="site" objname="imu_in_pelvis" name="global_angvel_pelvis"/>
    <framelinvel objtype="site" objname="left_foot" name="left_foot_global_linvel"/>
    <framelinvel objtype="site" objname="right_foot" name="right_foot_global_linvel"/>
    <framezaxis objtype="site" objname="left_foot" name="left_foot_upvector"/>
    <framezaxis objtype="site" objname="right_foot" name="right_foot_upvector"/>
    <force name="left_foot_force" site="left_foot"/>
    <force name="right_foot_force" site="right_foot"/>
  </sensor>
</mujoco>
